*** Starting uWSGI 2.0.19.1 (64bit) on [Sun Sep  5 20:32:04 2021] ***
compiled with version: 8.3.0 on 05 September 2021 20:31:25
os: Linux-5.10.47-linuxkit #1 SMP Sat Jul 3 21:51:47 UTC 2021
nodename: a01cf5db62a2
machine: x86_64
clock source: unix
pcre jit disabled
detected number of CPU cores: 2
current working directory: /var/www/html/flask_api
detected binary path: /usr/local/bin/uwsgi
uWSGI running as root, you can use --uid/--gid/--chroot options
*** WARNING: you are running uWSGI as root !!! (use the --uid flag) *** 
your memory page size is 4096 bytes
detected max file descriptor number: 1048576
lock engine: pthread robust mutexes
thunder lock: disabled (you can enable it with --thunder-lock)
uwsgi socket 0 bound to TCP address :8000 fd 3
uWSGI running as root, you can use --uid/--gid/--chroot options
*** WARNING: you are running uWSGI as root !!! (use the --uid flag) *** 
Python version: 3.9.2 (default, Mar 31 2021, 12:13:11)  [GCC 8.3.0]
Python main interpreter initialized at 0x556b5e923080
uWSGI running as root, you can use --uid/--gid/--chroot options
*** WARNING: you are running uWSGI as root !!! (use the --uid flag) *** 
python threads support enabled
your server socket listen backlog is limited to 100 connections
your mercy for graceful operations on workers is 60 seconds
mapped 416880 bytes (407 KB) for 8 cores
*** Operational MODE: preforking+threaded ***
WSGI app 0 (mountpoint='') ready in 2 seconds on interpreter 0x556b5e923080 pid: 11 (default app)
uWSGI running as root, you can use --uid/--gid/--chroot options
*** WARNING: you are running uWSGI as root !!! (use the --uid flag) *** 
spawned uWSGI master process (pid: 11)
spawned uWSGI worker 1 (pid: 12, cores: 2)
spawned uWSGI worker 2 (pid: 14, cores: 2)
spawned uWSGI worker 3 (pid: 16, cores: 2)
spawned uWSGI worker 4 (pid: 18, cores: 2)
Traceback (most recent call last):
  File "/usr/local/lib/python3.9/site-packages/sqlalchemy/engine/base.py", line 1771, in _execute_context
    self.dialect.do_execute(
  File "/usr/local/lib/python3.9/site-packages/sqlalchemy/engine/default.py", line 717, in do_execute
    cursor.execute(statement, parameters)
  File "/usr/local/lib/python3.9/site-packages/pymysql/cursors.py", line 148, in execute
    result = self._query(query)
  File "/usr/local/lib/python3.9/site-packages/pymysql/cursors.py", line 310, in _query
    conn.query(q)
  File "/usr/local/lib/python3.9/site-packages/pymysql/connections.py", line 548, in query
    self._affected_rows = self._read_query_result(unbuffered=unbuffered)
  File "/usr/local/lib/python3.9/site-packages/pymysql/connections.py", line 775, in _read_query_result
    result.read()
  File "/usr/local/lib/python3.9/site-packages/pymysql/connections.py", line 1156, in read
    first_packet = self.connection._read_packet()
  File "/usr/local/lib/python3.9/site-packages/pymysql/connections.py", line 725, in _read_packet
    packet.raise_for_error()
  File "/usr/local/lib/python3.9/site-packages/pymysql/protocol.py", line 221, in raise_for_error
    err.raise_mysql_exception(self._data)
  File "/usr/local/lib/python3.9/site-packages/pymysql/err.py", line 143, in raise_mysql_exception
    raise errorclass(errno, errval)
pymysql.err.ProgrammingError: (1146, "Table 'flask_api.admin' doesn't exist")

The above exception was the direct cause of the following exception:

Traceback (most recent call last):
  File "/usr/local/lib/python3.9/site-packages/flask/app.py", line 2088, in __call__
    return self.wsgi_app(environ, start_response)
  File "/usr/local/lib/python3.9/site-packages/flask/app.py", line 2073, in wsgi_app
    response = self.handle_exception(e)
  File "/usr/local/lib/python3.9/site-packages/flask_restful/__init__.py", line 271, in error_router
    return original_handler(e)
  File "/usr/local/lib/python3.9/site-packages/flask/app.py", line 2070, in wsgi_app
    response = self.full_dispatch_request()
  File "/usr/local/lib/python3.9/site-packages/flask/app.py", line 1515, in full_dispatch_request
    rv = self.handle_user_exception(e)
  File "/usr/local/lib/python3.9/site-packages/flask_restful/__init__.py", line 271, in error_router
    return original_handler(e)
  File "/usr/local/lib/python3.9/site-packages/flask/app.py", line 1513, in full_dispatch_request
    rv = self.dispatch_request()
  File "/usr/local/lib/python3.9/site-packages/flask/app.py", line 1499, in dispatch_request
    return self.ensure_sync(self.view_functions[rule.endpoint])(**req.view_args)
  File "/usr/local/lib/python3.9/site-packages/flask_restful/__init__.py", line 467, in wrapper
    resp = resource(*args, **kwargs)
  File "/usr/local/lib/python3.9/site-packages/flask/views.py", line 83, in view
    return self.dispatch_request(*args, **kwargs)
  File "/usr/local/lib/python3.9/site-packages/flask_restful/__init__.py", line 582, in dispatch_request
    resp = meth(*args, **kwargs)
  File "./employee_service/views.py", line 161, in post
    queryAdmin=Admin.query.filter_by(username=RequestPost['username']).count()
  File "/usr/local/lib/python3.9/site-packages/sqlalchemy/orm/query.py", line 3090, in count
    return self._from_self(col).enable_eagerloads(False).scalar()
  File "/usr/local/lib/python3.9/site-packages/sqlalchemy/orm/query.py", line 2831, in scalar
    ret = self.one()
  File "/usr/local/lib/python3.9/site-packages/sqlalchemy/orm/query.py", line 2808, in one
    return self._iter().one()
  File "/usr/local/lib/python3.9/site-packages/sqlalchemy/orm/query.py", line 2846, in _iter
    result = self.session.execute(
  File "/usr/local/lib/python3.9/site-packages/sqlalchemy/orm/session.py", line 1689, in execute
    result = conn._execute_20(statement, params or {}, execution_options)
  File "/usr/local/lib/python3.9/site-packages/sqlalchemy/engine/base.py", line 1583, in _execute_20
    return meth(self, args_10style, kwargs_10style, execution_options)
  File "/usr/local/lib/python3.9/site-packages/sqlalchemy/sql/elements.py", line 323, in _execute_on_connection
    return connection._execute_clauseelement(
  File "/usr/local/lib/python3.9/site-packages/sqlalchemy/engine/base.py", line 1452, in _execute_clauseelement
    ret = self._execute_context(
  File "/usr/local/lib/python3.9/site-packages/sqlalchemy/engine/base.py", line 1814, in _execute_context
    self._handle_dbapi_exception(
  File "/usr/local/lib/python3.9/site-packages/sqlalchemy/engine/base.py", line 1995, in _handle_dbapi_exception
    util.raise_(
  File "/usr/local/lib/python3.9/site-packages/sqlalchemy/util/compat.py", line 207, in raise_
    raise exception
  File "/usr/local/lib/python3.9/site-packages/sqlalchemy/engine/base.py", line 1771, in _execute_context
    self.dialect.do_execute(
  File "/usr/local/lib/python3.9/site-packages/sqlalchemy/engine/default.py", line 717, in do_execute
    cursor.execute(statement, parameters)
  File "/usr/local/lib/python3.9/site-packages/pymysql/cursors.py", line 148, in execute
    result = self._query(query)
  File "/usr/local/lib/python3.9/site-packages/pymysql/cursors.py", line 310, in _query
    conn.query(q)
  File "/usr/local/lib/python3.9/site-packages/pymysql/connections.py", line 548, in query
    self._affected_rows = self._read_query_result(unbuffered=unbuffered)
  File "/usr/local/lib/python3.9/site-packages/pymysql/connections.py", line 775, in _read_query_result
    result.read()
  File "/usr/local/lib/python3.9/site-packages/pymysql/connections.py", line 1156, in read
    first_packet = self.connection._read_packet()
  File "/usr/local/lib/python3.9/site-packages/pymysql/connections.py", line 725, in _read_packet
    packet.raise_for_error()
  File "/usr/local/lib/python3.9/site-packages/pymysql/protocol.py", line 221, in raise_for_error
    err.raise_mysql_exception(self._data)
  File "/usr/local/lib/python3.9/site-packages/pymysql/err.py", line 143, in raise_mysql_exception
    raise errorclass(errno, errval)
sqlalchemy.exc.ProgrammingError: (pymysql.err.ProgrammingError) (1146, "Table 'flask_api.admin' doesn't exist")
[SQL: SELECT count(*) AS count_1 
FROM (SELECT `admin`.id AS admin_id, `admin`.username AS admin_username, `admin`.`key` AS admin_key 
FROM `admin` 
WHERE `admin`.username = %(username_1)s) AS anon_1]
[parameters: {'username_1': 'IamRoot!!'}]
(Background on this error at: https://sqlalche.me/e/14/f405)
[pid: 18|app: 0|req: 1/1] 172.22.0.1 () {40 vars in 669 bytes} [Sun Sep  5 20:32:22 2021] POST /create_admin => generated 0 bytes in 639 msecs (HTTP/1.1 500) 0 headers in 0 bytes (0 switches on core 0)
Traceback (most recent call last):
  File "/usr/local/lib/python3.9/site-packages/sqlalchemy/engine/base.py", line 1771, in _execute_context
    self.dialect.do_execute(
  File "/usr/local/lib/python3.9/site-packages/sqlalchemy/engine/default.py", line 717, in do_execute
    cursor.execute(statement, parameters)
  File "/usr/local/lib/python3.9/site-packages/pymysql/cursors.py", line 148, in execute
    result = self._query(query)
  File "/usr/local/lib/python3.9/site-packages/pymysql/cursors.py", line 310, in _query
    conn.query(q)
  File "/usr/local/lib/python3.9/site-packages/pymysql/connections.py", line 548, in query
    self._affected_rows = self._read_query_result(unbuffered=unbuffered)
  File "/usr/local/lib/python3.9/site-packages/pymysql/connections.py", line 775, in _read_query_result
    result.read()
  File "/usr/local/lib/python3.9/site-packages/pymysql/connections.py", line 1156, in read
    first_packet = self.connection._read_packet()
  File "/usr/local/lib/python3.9/site-packages/pymysql/connections.py", line 725, in _read_packet
    packet.raise_for_error()
  File "/usr/local/lib/python3.9/site-packages/pymysql/protocol.py", line 221, in raise_for_error
    err.raise_mysql_exception(self._data)
  File "/usr/local/lib/python3.9/site-packages/pymysql/err.py", line 143, in raise_mysql_exception
    raise errorclass(errno, errval)
pymysql.err.ProgrammingError: (1146, "Table 'flask_api.admin' doesn't exist")

The above exception was the direct cause of the following exception:

Traceback (most recent call last):
  File "/usr/local/lib/python3.9/site-packages/flask/app.py", line 2088, in __call__
    return self.wsgi_app(environ, start_response)
  File "/usr/local/lib/python3.9/site-packages/flask/app.py", line 2073, in wsgi_app
    response = self.handle_exception(e)
  File "/usr/local/lib/python3.9/site-packages/flask_restful/__init__.py", line 271, in error_router
    return original_handler(e)
  File "/usr/local/lib/python3.9/site-packages/flask/app.py", line 2070, in wsgi_app
    response = self.full_dispatch_request()
  File "/usr/local/lib/python3.9/site-packages/flask/app.py", line 1515, in full_dispatch_request
    rv = self.handle_user_exception(e)
  File "/usr/local/lib/python3.9/site-packages/flask_restful/__init__.py", line 271, in error_router
    return original_handler(e)
  File "/usr/local/lib/python3.9/site-packages/flask/app.py", line 1513, in full_dispatch_request
    rv = self.dispatch_request()
  File "/usr/local/lib/python3.9/site-packages/flask/app.py", line 1499, in dispatch_request
    return self.ensure_sync(self.view_functions[rule.endpoint])(**req.view_args)
  File "/usr/local/lib/python3.9/site-packages/flask_restful/__init__.py", line 467, in wrapper
    resp = resource(*args, **kwargs)
  File "/usr/local/lib/python3.9/site-packages/flask/views.py", line 83, in view
    return self.dispatch_request(*args, **kwargs)
  File "/usr/local/lib/python3.9/site-packages/flask_restful/__init__.py", line 582, in dispatch_request
    resp = meth(*args, **kwargs)
  File "./employee_service/views.py", line 161, in post
    queryAdmin=Admin.query.filter_by(username=RequestPost['username']).count()
  File "/usr/local/lib/python3.9/site-packages/sqlalchemy/orm/query.py", line 3090, in count
    return self._from_self(col).enable_eagerloads(False).scalar()
  File "/usr/local/lib/python3.9/site-packages/sqlalchemy/orm/query.py", line 2831, in scalar
    ret = self.one()
  File "/usr/local/lib/python3.9/site-packages/sqlalchemy/orm/query.py", line 2808, in one
    return self._iter().one()
  File "/usr/local/lib/python3.9/site-packages/sqlalchemy/orm/query.py", line 2846, in _iter
    result = self.session.execute(
  File "/usr/local/lib/python3.9/site-packages/sqlalchemy/orm/session.py", line 1689, in execute
    result = conn._execute_20(statement, params or {}, execution_options)
  File "/usr/local/lib/python3.9/site-packages/sqlalchemy/engine/base.py", line 1583, in _execute_20
    return meth(self, args_10style, kwargs_10style, execution_options)
  File "/usr/local/lib/python3.9/site-packages/sqlalchemy/sql/elements.py", line 323, in _execute_on_connection
    return connection._execute_clauseelement(
  File "/usr/local/lib/python3.9/site-packages/sqlalchemy/engine/base.py", line 1452, in _execute_clauseelement
    ret = self._execute_context(
  File "/usr/local/lib/python3.9/site-packages/sqlalchemy/engine/base.py", line 1814, in _execute_context
    self._handle_dbapi_exception(
  File "/usr/local/lib/python3.9/site-packages/sqlalchemy/engine/base.py", line 1995, in _handle_dbapi_exception
    util.raise_(
  File "/usr/local/lib/python3.9/site-packages/sqlalchemy/util/compat.py", line 207, in raise_
    raise exception
  File "/usr/local/lib/python3.9/site-packages/sqlalchemy/engine/base.py", line 1771, in _execute_context
    self.dialect.do_execute(
  File "/usr/local/lib/python3.9/site-packages/sqlalchemy/engine/default.py", line 717, in do_execute
    cursor.execute(statement, parameters)
  File "/usr/local/lib/python3.9/site-packages/pymysql/cursors.py", line 148, in execute
    result = self._query(query)
  File "/usr/local/lib/python3.9/site-packages/pymysql/cursors.py", line 310, in _query
    conn.query(q)
  File "/usr/local/lib/python3.9/site-packages/pymysql/connections.py", line 548, in query
    self._affected_rows = self._read_query_result(unbuffered=unbuffered)
  File "/usr/local/lib/python3.9/site-packages/pymysql/connections.py", line 775, in _read_query_result
    result.read()
  File "/usr/local/lib/python3.9/site-packages/pymysql/connections.py", line 1156, in read
    first_packet = self.connection._read_packet()
  File "/usr/local/lib/python3.9/site-packages/pymysql/connections.py", line 725, in _read_packet
    packet.raise_for_error()
  File "/usr/local/lib/python3.9/site-packages/pymysql/protocol.py", line 221, in raise_for_error
    err.raise_mysql_exception(self._data)
  File "/usr/local/lib/python3.9/site-packages/pymysql/err.py", line 143, in raise_mysql_exception
    raise errorclass(errno, errval)
sqlalchemy.exc.ProgrammingError: (pymysql.err.ProgrammingError) (1146, "Table 'flask_api.admin' doesn't exist")
[SQL: SELECT count(*) AS count_1 
FROM (SELECT `admin`.id AS admin_id, `admin`.username AS admin_username, `admin`.`key` AS admin_key 
FROM `admin` 
WHERE `admin`.username = %(username_1)s) AS anon_1]
[parameters: {'username_1': 'IamRoot!!'}]
(Background on this error at: https://sqlalche.me/e/14/f405)
[pid: 18|app: 0|req: 2/2] 172.22.0.1 () {40 vars in 669 bytes} [Sun Sep  5 20:32:45 2021] POST /create_admin => generated 0 bytes in 201 msecs (HTTP/1.1 500) 0 headers in 0 bytes (0 switches on core 1)
Traceback (most recent call last):
  File "/usr/local/lib/python3.9/site-packages/sqlalchemy/engine/base.py", line 1771, in _execute_context
    self.dialect.do_execute(
  File "/usr/local/lib/python3.9/site-packages/sqlalchemy/engine/default.py", line 717, in do_execute
    cursor.execute(statement, parameters)
  File "/usr/local/lib/python3.9/site-packages/pymysql/cursors.py", line 148, in execute
    result = self._query(query)
  File "/usr/local/lib/python3.9/site-packages/pymysql/cursors.py", line 310, in _query
    conn.query(q)
  File "/usr/local/lib/python3.9/site-packages/pymysql/connections.py", line 548, in query
    self._affected_rows = self._read_query_result(unbuffered=unbuffered)
  File "/usr/local/lib/python3.9/site-packages/pymysql/connections.py", line 775, in _read_query_result
    result.read()
  File "/usr/local/lib/python3.9/site-packages/pymysql/connections.py", line 1156, in read
    first_packet = self.connection._read_packet()
  File "/usr/local/lib/python3.9/site-packages/pymysql/connections.py", line 725, in _read_packet
    packet.raise_for_error()
  File "/usr/local/lib/python3.9/site-packages/pymysql/protocol.py", line 221, in raise_for_error
    err.raise_mysql_exception(self._data)
  File "/usr/local/lib/python3.9/site-packages/pymysql/err.py", line 143, in raise_mysql_exception
    raise errorclass(errno, errval)
pymysql.err.ProgrammingError: (1146, "Table 'flask_api.admin' doesn't exist")

The above exception was the direct cause of the following exception:

Traceback (most recent call last):
  File "/usr/local/lib/python3.9/site-packages/flask/app.py", line 2088, in __call__
    return self.wsgi_app(environ, start_response)
  File "/usr/local/lib/python3.9/site-packages/flask/app.py", line 2073, in wsgi_app
    response = self.handle_exception(e)
  File "/usr/local/lib/python3.9/site-packages/flask_restful/__init__.py", line 271, in error_router
    return original_handler(e)
  File "/usr/local/lib/python3.9/site-packages/flask/app.py", line 2070, in wsgi_app
    response = self.full_dispatch_request()
  File "/usr/local/lib/python3.9/site-packages/flask/app.py", line 1515, in full_dispatch_request
    rv = self.handle_user_exception(e)
  File "/usr/local/lib/python3.9/site-packages/flask_restful/__init__.py", line 271, in error_router
    return original_handler(e)
  File "/usr/local/lib/python3.9/site-packages/flask/app.py", line 1513, in full_dispatch_request
    rv = self.dispatch_request()
  File "/usr/local/lib/python3.9/site-packages/flask/app.py", line 1499, in dispatch_request
    return self.ensure_sync(self.view_functions[rule.endpoint])(**req.view_args)
  File "/usr/local/lib/python3.9/site-packages/flask_restful/__init__.py", line 467, in wrapper
    resp = resource(*args, **kwargs)
  File "/usr/local/lib/python3.9/site-packages/flask/views.py", line 83, in view
    return self.dispatch_request(*args, **kwargs)
  File "/usr/local/lib/python3.9/site-packages/flask_restful/__init__.py", line 582, in dispatch_request
    resp = meth(*args, **kwargs)
  File "./employee_service/views.py", line 161, in post
    queryAdmin=Admin.query.filter_by(username=RequestPost['username']).count()
  File "/usr/local/lib/python3.9/site-packages/sqlalchemy/orm/query.py", line 3090, in count
    return self._from_self(col).enable_eagerloads(False).scalar()
  File "/usr/local/lib/python3.9/site-packages/sqlalchemy/orm/query.py", line 2831, in scalar
    ret = self.one()
  File "/usr/local/lib/python3.9/site-packages/sqlalchemy/orm/query.py", line 2808, in one
    return self._iter().one()
  File "/usr/local/lib/python3.9/site-packages/sqlalchemy/orm/query.py", line 2846, in _iter
    result = self.session.execute(
  File "/usr/local/lib/python3.9/site-packages/sqlalchemy/orm/session.py", line 1689, in execute
    result = conn._execute_20(statement, params or {}, execution_options)
  File "/usr/local/lib/python3.9/site-packages/sqlalchemy/engine/base.py", line 1583, in _execute_20
    return meth(self, args_10style, kwargs_10style, execution_options)
  File "/usr/local/lib/python3.9/site-packages/sqlalchemy/sql/elements.py", line 323, in _execute_on_connection
    return connection._execute_clauseelement(
  File "/usr/local/lib/python3.9/site-packages/sqlalchemy/engine/base.py", line 1452, in _execute_clauseelement
    ret = self._execute_context(
  File "/usr/local/lib/python3.9/site-packages/sqlalchemy/engine/base.py", line 1814, in _execute_context
    self._handle_dbapi_exception(
  File "/usr/local/lib/python3.9/site-packages/sqlalchemy/engine/base.py", line 1995, in _handle_dbapi_exception
    util.raise_(
  File "/usr/local/lib/python3.9/site-packages/sqlalchemy/util/compat.py", line 207, in raise_
    raise exception
  File "/usr/local/lib/python3.9/site-packages/sqlalchemy/engine/base.py", line 1771, in _execute_context
    self.dialect.do_execute(
  File "/usr/local/lib/python3.9/site-packages/sqlalchemy/engine/default.py", line 717, in do_execute
    cursor.execute(statement, parameters)
  File "/usr/local/lib/python3.9/site-packages/pymysql/cursors.py", line 148, in execute
    result = self._query(query)
  File "/usr/local/lib/python3.9/site-packages/pymysql/cursors.py", line 310, in _query
    conn.query(q)
  File "/usr/local/lib/python3.9/site-packages/pymysql/connections.py", line 548, in query
    self._affected_rows = self._read_query_result(unbuffered=unbuffered)
  File "/usr/local/lib/python3.9/site-packages/pymysql/connections.py", line 775, in _read_query_result
    result.read()
  File "/usr/local/lib/python3.9/site-packages/pymysql/connections.py", line 1156, in read
    first_packet = self.connection._read_packet()
  File "/usr/local/lib/python3.9/site-packages/pymysql/connections.py", line 725, in _read_packet
    packet.raise_for_error()
  File "/usr/local/lib/python3.9/site-packages/pymysql/protocol.py", line 221, in raise_for_error
    err.raise_mysql_exception(self._data)
  File "/usr/local/lib/python3.9/site-packages/pymysql/err.py", line 143, in raise_mysql_exception
    raise errorclass(errno, errval)
sqlalchemy.exc.ProgrammingError: (pymysql.err.ProgrammingError) (1146, "Table 'flask_api.admin' doesn't exist")
[SQL: SELECT count(*) AS count_1 
FROM (SELECT `admin`.id AS admin_id, `admin`.username AS admin_username, `admin`.`key` AS admin_key 
FROM `admin` 
WHERE `admin`.username = %(username_1)s) AS anon_1]
[parameters: {'username_1': 'IamRoot!!'}]
(Background on this error at: https://sqlalche.me/e/14/f405)
[pid: 18|app: 0|req: 3/3] 172.22.0.1 () {40 vars in 669 bytes} [Sun Sep  5 20:32:46 2021] POST /create_admin => generated 0 bytes in 270 msecs (HTTP/1.1 500) 0 headers in 0 bytes (0 switches on core 0)
Traceback (most recent call last):
  File "/usr/local/lib/python3.9/site-packages/sqlalchemy/engine/base.py", line 1771, in _execute_context
    self.dialect.do_execute(
  File "/usr/local/lib/python3.9/site-packages/sqlalchemy/engine/default.py", line 717, in do_execute
    cursor.execute(statement, parameters)
  File "/usr/local/lib/python3.9/site-packages/pymysql/cursors.py", line 148, in execute
    result = self._query(query)
  File "/usr/local/lib/python3.9/site-packages/pymysql/cursors.py", line 310, in _query
    conn.query(q)
  File "/usr/local/lib/python3.9/site-packages/pymysql/connections.py", line 548, in query
    self._affected_rows = self._read_query_result(unbuffered=unbuffered)
  File "/usr/local/lib/python3.9/site-packages/pymysql/connections.py", line 775, in _read_query_result
    result.read()
  File "/usr/local/lib/python3.9/site-packages/pymysql/connections.py", line 1156, in read
    first_packet = self.connection._read_packet()
  File "/usr/local/lib/python3.9/site-packages/pymysql/connections.py", line 725, in _read_packet
    packet.raise_for_error()
  File "/usr/local/lib/python3.9/site-packages/pymysql/protocol.py", line 221, in raise_for_error
    err.raise_mysql_exception(self._data)
  File "/usr/local/lib/python3.9/site-packages/pymysql/err.py", line 143, in raise_mysql_exception
    raise errorclass(errno, errval)
pymysql.err.ProgrammingError: (1146, "Table 'flask_api.admin' doesn't exist")

The above exception was the direct cause of the following exception:

Traceback (most recent call last):
  File "/usr/local/lib/python3.9/site-packages/flask/app.py", line 2088, in __call__
    return self.wsgi_app(environ, start_response)
  File "/usr/local/lib/python3.9/site-packages/flask/app.py", line 2073, in wsgi_app
    response = self.handle_exception(e)
  File "/usr/local/lib/python3.9/site-packages/flask_restful/__init__.py", line 271, in error_router
    return original_handler(e)
  File "/usr/local/lib/python3.9/site-packages/flask/app.py", line 2070, in wsgi_app
    response = self.full_dispatch_request()
  File "/usr/local/lib/python3.9/site-packages/flask/app.py", line 1515, in full_dispatch_request
    rv = self.handle_user_exception(e)
  File "/usr/local/lib/python3.9/site-packages/flask_restful/__init__.py", line 271, in error_router
    return original_handler(e)
  File "/usr/local/lib/python3.9/site-packages/flask/app.py", line 1513, in full_dispatch_request
    rv = self.dispatch_request()
  File "/usr/local/lib/python3.9/site-packages/flask/app.py", line 1499, in dispatch_request
    return self.ensure_sync(self.view_functions[rule.endpoint])(**req.view_args)
  File "/usr/local/lib/python3.9/site-packages/flask_restful/__init__.py", line 467, in wrapper
    resp = resource(*args, **kwargs)
  File "/usr/local/lib/python3.9/site-packages/flask/views.py", line 83, in view
    return self.dispatch_request(*args, **kwargs)
  File "/usr/local/lib/python3.9/site-packages/flask_restful/__init__.py", line 582, in dispatch_request
    resp = meth(*args, **kwargs)
  File "./employee_service/views.py", line 161, in post
    queryAdmin=Admin.query.filter_by(username=RequestPost['username']).count()
  File "/usr/local/lib/python3.9/site-packages/sqlalchemy/orm/query.py", line 3090, in count
    return self._from_self(col).enable_eagerloads(False).scalar()
  File "/usr/local/lib/python3.9/site-packages/sqlalchemy/orm/query.py", line 2831, in scalar
    ret = self.one()
  File "/usr/local/lib/python3.9/site-packages/sqlalchemy/orm/query.py", line 2808, in one
    return self._iter().one()
  File "/usr/local/lib/python3.9/site-packages/sqlalchemy/orm/query.py", line 2846, in _iter
    result = self.session.execute(
  File "/usr/local/lib/python3.9/site-packages/sqlalchemy/orm/session.py", line 1689, in execute
    result = conn._execute_20(statement, params or {}, execution_options)
  File "/usr/local/lib/python3.9/site-packages/sqlalchemy/engine/base.py", line 1583, in _execute_20
    return meth(self, args_10style, kwargs_10style, execution_options)
  File "/usr/local/lib/python3.9/site-packages/sqlalchemy/sql/elements.py", line 323, in _execute_on_connection
    return connection._execute_clauseelement(
  File "/usr/local/lib/python3.9/site-packages/sqlalchemy/engine/base.py", line 1452, in _execute_clauseelement
    ret = self._execute_context(
  File "/usr/local/lib/python3.9/site-packages/sqlalchemy/engine/base.py", line 1814, in _execute_context
    self._handle_dbapi_exception(
  File "/usr/local/lib/python3.9/site-packages/sqlalchemy/engine/base.py", line 1995, in _handle_dbapi_exception
    util.raise_(
  File "/usr/local/lib/python3.9/site-packages/sqlalchemy/util/compat.py", line 207, in raise_
    raise exception
  File "/usr/local/lib/python3.9/site-packages/sqlalchemy/engine/base.py", line 1771, in _execute_context
    self.dialect.do_execute(
  File "/usr/local/lib/python3.9/site-packages/sqlalchemy/engine/default.py", line 717, in do_execute
    cursor.execute(statement, parameters)
  File "/usr/local/lib/python3.9/site-packages/pymysql/cursors.py", line 148, in execute
    result = self._query(query)
  File "/usr/local/lib/python3.9/site-packages/pymysql/cursors.py", line 310, in _query
    conn.query(q)
  File "/usr/local/lib/python3.9/site-packages/pymysql/connections.py", line 548, in query
    self._affected_rows = self._read_query_result(unbuffered=unbuffered)
  File "/usr/local/lib/python3.9/site-packages/pymysql/connections.py", line 775, in _read_query_result
    result.read()
  File "/usr/local/lib/python3.9/site-packages/pymysql/connections.py", line 1156, in read
    first_packet = self.connection._read_packet()
  File "/usr/local/lib/python3.9/site-packages/pymysql/connections.py", line 725, in _read_packet
    packet.raise_for_error()
  File "/usr/local/lib/python3.9/site-packages/pymysql/protocol.py", line 221, in raise_for_error
    err.raise_mysql_exception(self._data)
  File "/usr/local/lib/python3.9/site-packages/pymysql/err.py", line 143, in raise_mysql_exception
    raise errorclass(errno, errval)
sqlalchemy.exc.ProgrammingError: (pymysql.err.ProgrammingError) (1146, "Table 'flask_api.admin' doesn't exist")
[SQL: SELECT count(*) AS count_1 
FROM (SELECT `admin`.id AS admin_id, `admin`.username AS admin_username, `admin`.`key` AS admin_key 
FROM `admin` 
WHERE `admin`.username = %(username_1)s) AS anon_1]
[parameters: {'username_1': 'IamRoot!!'}]
(Background on this error at: https://sqlalche.me/e/14/f405)
[pid: 18|app: 0|req: 4/4] 172.22.0.1 () {40 vars in 669 bytes} [Sun Sep  5 20:32:47 2021] POST /create_admin => generated 0 bytes in 202 msecs (HTTP/1.1 500) 0 headers in 0 bytes (0 switches on core 1)
Traceback (most recent call last):
  File "/usr/local/lib/python3.9/site-packages/sqlalchemy/engine/base.py", line 1771, in _execute_context
    self.dialect.do_execute(
  File "/usr/local/lib/python3.9/site-packages/sqlalchemy/engine/default.py", line 717, in do_execute
    cursor.execute(statement, parameters)
  File "/usr/local/lib/python3.9/site-packages/pymysql/cursors.py", line 148, in execute
    result = self._query(query)
  File "/usr/local/lib/python3.9/site-packages/pymysql/cursors.py", line 310, in _query
    conn.query(q)
  File "/usr/local/lib/python3.9/site-packages/pymysql/connections.py", line 548, in query
    self._affected_rows = self._read_query_result(unbuffered=unbuffered)
  File "/usr/local/lib/python3.9/site-packages/pymysql/connections.py", line 775, in _read_query_result
    result.read()
  File "/usr/local/lib/python3.9/site-packages/pymysql/connections.py", line 1156, in read
    first_packet = self.connection._read_packet()
  File "/usr/local/lib/python3.9/site-packages/pymysql/connections.py", line 725, in _read_packet
    packet.raise_for_error()
  File "/usr/local/lib/python3.9/site-packages/pymysql/protocol.py", line 221, in raise_for_error
    err.raise_mysql_exception(self._data)
  File "/usr/local/lib/python3.9/site-packages/pymysql/err.py", line 143, in raise_mysql_exception
    raise errorclass(errno, errval)
pymysql.err.ProgrammingError: (1146, "Table 'flask_api.admin' doesn't exist")

The above exception was the direct cause of the following exception:

Traceback (most recent call last):
  File "/usr/local/lib/python3.9/site-packages/flask/app.py", line 2088, in __call__
    return self.wsgi_app(environ, start_response)
  File "/usr/local/lib/python3.9/site-packages/flask/app.py", line 2073, in wsgi_app
    response = self.handle_exception(e)
  File "/usr/local/lib/python3.9/site-packages/flask_restful/__init__.py", line 271, in error_router
    return original_handler(e)
  File "/usr/local/lib/python3.9/site-packages/flask/app.py", line 2070, in wsgi_app
    response = self.full_dispatch_request()
  File "/usr/local/lib/python3.9/site-packages/flask/app.py", line 1515, in full_dispatch_request
    rv = self.handle_user_exception(e)
  File "/usr/local/lib/python3.9/site-packages/flask_restful/__init__.py", line 271, in error_router
    return original_handler(e)
  File "/usr/local/lib/python3.9/site-packages/flask/app.py", line 1513, in full_dispatch_request
    rv = self.dispatch_request()
  File "/usr/local/lib/python3.9/site-packages/flask/app.py", line 1499, in dispatch_request
    return self.ensure_sync(self.view_functions[rule.endpoint])(**req.view_args)
  File "/usr/local/lib/python3.9/site-packages/flask_restful/__init__.py", line 467, in wrapper
    resp = resource(*args, **kwargs)
  File "/usr/local/lib/python3.9/site-packages/flask/views.py", line 83, in view
    return self.dispatch_request(*args, **kwargs)
  File "/usr/local/lib/python3.9/site-packages/flask_restful/__init__.py", line 582, in dispatch_request
    resp = meth(*args, **kwargs)
  File "./employee_service/views.py", line 161, in post
    queryAdmin=Admin.query.filter_by(username=RequestPost['username']).count()
  File "/usr/local/lib/python3.9/site-packages/sqlalchemy/orm/query.py", line 3090, in count
    return self._from_self(col).enable_eagerloads(False).scalar()
  File "/usr/local/lib/python3.9/site-packages/sqlalchemy/orm/query.py", line 2831, in scalar
    ret = self.one()
  File "/usr/local/lib/python3.9/site-packages/sqlalchemy/orm/query.py", line 2808, in one
    return self._iter().one()
  File "/usr/local/lib/python3.9/site-packages/sqlalchemy/orm/query.py", line 2846, in _iter
    result = self.session.execute(
  File "/usr/local/lib/python3.9/site-packages/sqlalchemy/orm/session.py", line 1689, in execute
    result = conn._execute_20(statement, params or {}, execution_options)
  File "/usr/local/lib/python3.9/site-packages/sqlalchemy/engine/base.py", line 1583, in _execute_20
    return meth(self, args_10style, kwargs_10style, execution_options)
  File "/usr/local/lib/python3.9/site-packages/sqlalchemy/sql/elements.py", line 323, in _execute_on_connection
    return connection._execute_clauseelement(
  File "/usr/local/lib/python3.9/site-packages/sqlalchemy/engine/base.py", line 1452, in _execute_clauseelement
    ret = self._execute_context(
  File "/usr/local/lib/python3.9/site-packages/sqlalchemy/engine/base.py", line 1814, in _execute_context
    self._handle_dbapi_exception(
  File "/usr/local/lib/python3.9/site-packages/sqlalchemy/engine/base.py", line 1995, in _handle_dbapi_exception
    util.raise_(
  File "/usr/local/lib/python3.9/site-packages/sqlalchemy/util/compat.py", line 207, in raise_
    raise exception
  File "/usr/local/lib/python3.9/site-packages/sqlalchemy/engine/base.py", line 1771, in _execute_context
    self.dialect.do_execute(
  File "/usr/local/lib/python3.9/site-packages/sqlalchemy/engine/default.py", line 717, in do_execute
    cursor.execute(statement, parameters)
  File "/usr/local/lib/python3.9/site-packages/pymysql/cursors.py", line 148, in execute
    result = self._query(query)
  File "/usr/local/lib/python3.9/site-packages/pymysql/cursors.py", line 310, in _query
    conn.query(q)
  File "/usr/local/lib/python3.9/site-packages/pymysql/connections.py", line 548, in query
    self._affected_rows = self._read_query_result(unbuffered=unbuffered)
  File "/usr/local/lib/python3.9/site-packages/pymysql/connections.py", line 775, in _read_query_result
    result.read()
  File "/usr/local/lib/python3.9/site-packages/pymysql/connections.py", line 1156, in read
    first_packet = self.connection._read_packet()
  File "/usr/local/lib/python3.9/site-packages/pymysql/connections.py", line 725, in _read_packet
    packet.raise_for_error()
  File "/usr/local/lib/python3.9/site-packages/pymysql/protocol.py", line 221, in raise_for_error
    err.raise_mysql_exception(self._data)
  File "/usr/local/lib/python3.9/site-packages/pymysql/err.py", line 143, in raise_mysql_exception
    raise errorclass(errno, errval)
sqlalchemy.exc.ProgrammingError: (pymysql.err.ProgrammingError) (1146, "Table 'flask_api.admin' doesn't exist")
[SQL: SELECT count(*) AS count_1 
FROM (SELECT `admin`.id AS admin_id, `admin`.username AS admin_username, `admin`.`key` AS admin_key 
FROM `admin` 
WHERE `admin`.username = %(username_1)s) AS anon_1]
[parameters: {'username_1': 'IamRoot!!'}]
(Background on this error at: https://sqlalche.me/e/14/f405)
[pid: 18|app: 0|req: 5/5] 172.22.0.1 () {40 vars in 669 bytes} [Sun Sep  5 20:34:17 2021] POST /create_admin => generated 0 bytes in 145 msecs (HTTP/1.1 500) 0 headers in 0 bytes (0 switches on core 0)
*** Starting uWSGI 2.0.19.1 (64bit) on [Sun Sep  5 20:36:44 2021] ***
compiled with version: 8.3.0 on 05 September 2021 20:31:25
os: Linux-5.10.47-linuxkit #1 SMP Sat Jul 3 21:51:47 UTC 2021
nodename: a01cf5db62a2
machine: x86_64
clock source: unix
pcre jit disabled
detected number of CPU cores: 2
current working directory: /var/www/html/flask_api
detected binary path: /usr/local/bin/uwsgi
uWSGI running as root, you can use --uid/--gid/--chroot options
*** WARNING: you are running uWSGI as root !!! (use the --uid flag) *** 
your memory page size is 4096 bytes
detected max file descriptor number: 1048576
lock engine: pthread robust mutexes
thunder lock: disabled (you can enable it with --thunder-lock)
uwsgi socket 0 bound to TCP address :8000 fd 3
uWSGI running as root, you can use --uid/--gid/--chroot options
*** WARNING: you are running uWSGI as root !!! (use the --uid flag) *** 
Python version: 3.9.2 (default, Mar 31 2021, 12:13:11)  [GCC 8.3.0]
Python main interpreter initialized at 0x55900d1f3080
uWSGI running as root, you can use --uid/--gid/--chroot options
*** WARNING: you are running uWSGI as root !!! (use the --uid flag) *** 
python threads support enabled
your server socket listen backlog is limited to 100 connections
your mercy for graceful operations on workers is 60 seconds
mapped 416880 bytes (407 KB) for 8 cores
*** Operational MODE: preforking+threaded ***
WSGI app 0 (mountpoint='') ready in 1 seconds on interpreter 0x55900d1f3080 pid: 10 (default app)
uWSGI running as root, you can use --uid/--gid/--chroot options
*** WARNING: you are running uWSGI as root !!! (use the --uid flag) *** 
spawned uWSGI master process (pid: 10)
spawned uWSGI worker 1 (pid: 11, cores: 2)
spawned uWSGI worker 2 (pid: 13, cores: 2)
spawned uWSGI worker 3 (pid: 15, cores: 2)
spawned uWSGI worker 4 (pid: 17, cores: 2)
[pid: 15|app: 0|req: 1/1] 172.22.0.1 () {40 vars in 669 bytes} [Sun Sep  5 20:36:46 2021] POST /create_admin => generated 39 bytes in 95 msecs (HTTP/1.1 200) 3 headers in 304 bytes (1 switches on core 0)
*** Starting uWSGI 2.0.19.1 (64bit) on [Sun Sep  5 20:54:02 2021] ***
compiled with version: 8.3.0 on 05 September 2021 20:49:27
os: Linux-5.10.47-linuxkit #1 SMP Sat Jul 3 21:51:47 UTC 2021
nodename: 369870bc2fd9
machine: x86_64
clock source: unix
pcre jit disabled
detected number of CPU cores: 2
current working directory: /var/www/html/flask_api
detected binary path: /usr/local/bin/uwsgi
uWSGI running as root, you can use --uid/--gid/--chroot options
*** WARNING: you are running uWSGI as root !!! (use the --uid flag) *** 
your memory page size is 4096 bytes
detected max file descriptor number: 1048576
lock engine: pthread robust mutexes
thunder lock: disabled (you can enable it with --thunder-lock)
uwsgi socket 0 bound to TCP address :8000 fd 3
uWSGI running as root, you can use --uid/--gid/--chroot options
*** WARNING: you are running uWSGI as root !!! (use the --uid flag) *** 
Python version: 3.9.2 (default, Mar 31 2021, 12:13:11)  [GCC 8.3.0]
Python main interpreter initialized at 0x56110bce70e0
uWSGI running as root, you can use --uid/--gid/--chroot options
*** WARNING: you are running uWSGI as root !!! (use the --uid flag) *** 
python threads support enabled
your server socket listen backlog is limited to 100 connections
your mercy for graceful operations on workers is 60 seconds
mapped 416880 bytes (407 KB) for 8 cores
*** Operational MODE: preforking+threaded ***
WSGI app 0 (mountpoint='') ready in 1 seconds on interpreter 0x56110bce70e0 pid: 28 (default app)
uWSGI running as root, you can use --uid/--gid/--chroot options
*** WARNING: you are running uWSGI as root !!! (use the --uid flag) *** 
spawned uWSGI master process (pid: 28)
spawned uWSGI worker 1 (pid: 29, cores: 2)
spawned uWSGI worker 2 (pid: 31, cores: 2)
spawned uWSGI worker 3 (pid: 33, cores: 2)
spawned uWSGI worker 4 (pid: 35, cores: 2)
[pid: 33|app: 0|req: 1/1] 172.27.0.1 () {40 vars in 669 bytes} [Sun Sep  5 20:54:23 2021] POST /create_admin => generated 39 bytes in 88 msecs (HTTP/1.1 200) 3 headers in 304 bytes (1 switches on core 0)
SIGINT/SIGQUIT received...killing workers...
worker 1 buried after 1 seconds
worker 2 buried after 1 seconds
worker 3 buried after 1 seconds
worker 4 buried after 1 seconds
goodbye to uWSGI.
*** Starting uWSGI 2.0.19.1 (64bit) on [Sun Sep  5 20:58:38 2021] ***
compiled with version: 8.3.0 on 05 September 2021 20:49:27
os: Linux-5.10.47-linuxkit #1 SMP Sat Jul 3 21:51:47 UTC 2021
nodename: ac66c95e306c
machine: x86_64
clock source: unix
pcre jit disabled
detected number of CPU cores: 2
current working directory: /var/www/html/flask_api
detected binary path: /usr/local/bin/uwsgi
uWSGI running as root, you can use --uid/--gid/--chroot options
*** WARNING: you are running uWSGI as root !!! (use the --uid flag) *** 
your memory page size is 4096 bytes
detected max file descriptor number: 1048576
lock engine: pthread robust mutexes
thunder lock: disabled (you can enable it with --thunder-lock)
uwsgi socket 0 bound to TCP address :8000 fd 3
uWSGI running as root, you can use --uid/--gid/--chroot options
*** WARNING: you are running uWSGI as root !!! (use the --uid flag) *** 
Python version: 3.9.2 (default, Mar 31 2021, 12:13:11)  [GCC 8.3.0]
Python main interpreter initialized at 0x5614c0e72080
uWSGI running as root, you can use --uid/--gid/--chroot options
*** WARNING: you are running uWSGI as root !!! (use the --uid flag) *** 
python threads support enabled
your server socket listen backlog is limited to 100 connections
your mercy for graceful operations on workers is 60 seconds
mapped 416880 bytes (407 KB) for 8 cores
*** Operational MODE: preforking+threaded ***
WSGI app 0 (mountpoint='') ready in 0 seconds on interpreter 0x5614c0e72080 pid: 14 (default app)
uWSGI running as root, you can use --uid/--gid/--chroot options
*** WARNING: you are running uWSGI as root !!! (use the --uid flag) *** 
spawned uWSGI master process (pid: 14)
spawned uWSGI worker 1 (pid: 15, cores: 2)
spawned uWSGI worker 2 (pid: 17, cores: 2)
spawned uWSGI worker 3 (pid: 18, cores: 2)
spawned uWSGI worker 4 (pid: 21, cores: 2)
[pid: 15|app: 0|req: 1/1] 172.28.0.1 () {42 vars in 1324 bytes} [Sun Sep  5 20:58:44 2021] GET /test => generated 4 bytes in 5 msecs (HTTP/1.1 200) 2 headers in 78 bytes (1 switches on core 0)
*** Starting uWSGI 2.0.19.1 (64bit) on [Mon Sep  6 06:34:39 2021] ***
compiled with version: 8.3.0 on 05 September 2021 20:49:27
os: Linux-5.10.47-linuxkit #1 SMP Sat Jul 3 21:51:47 UTC 2021
nodename: 7428ed25c5fa
machine: x86_64
clock source: unix
pcre jit disabled
detected number of CPU cores: 2
current working directory: /var/www/html/flask_api
detected binary path: /usr/local/bin/uwsgi
uWSGI running as root, you can use --uid/--gid/--chroot options
*** WARNING: you are running uWSGI as root !!! (use the --uid flag) *** 
your memory page size is 4096 bytes
detected max file descriptor number: 1048576
lock engine: pthread robust mutexes
thunder lock: disabled (you can enable it with --thunder-lock)
uwsgi socket 0 bound to TCP address :8000 fd 3
uWSGI running as root, you can use --uid/--gid/--chroot options
*** WARNING: you are running uWSGI as root !!! (use the --uid flag) *** 
Python version: 3.9.2 (default, Mar 31 2021, 12:13:11)  [GCC 8.3.0]
Python main interpreter initialized at 0x557b08163080
uWSGI running as root, you can use --uid/--gid/--chroot options
*** WARNING: you are running uWSGI as root !!! (use the --uid flag) *** 
python threads support enabled
your server socket listen backlog is limited to 100 connections
your mercy for graceful operations on workers is 60 seconds
mapped 416880 bytes (407 KB) for 8 cores
*** Operational MODE: preforking+threaded ***
WSGI app 0 (mountpoint='') ready in 3 seconds on interpreter 0x557b08163080 pid: 7 (default app)
uWSGI running as root, you can use --uid/--gid/--chroot options
*** WARNING: you are running uWSGI as root !!! (use the --uid flag) *** 
spawned uWSGI master process (pid: 7)
spawned uWSGI worker 1 (pid: 8, cores: 2)
spawned uWSGI worker 2 (pid: 10, cores: 2)
spawned uWSGI worker 3 (pid: 11, cores: 2)
spawned uWSGI worker 4 (pid: 14, cores: 2)
[pid: 14|app: 0|req: 1/1] 192.168.16.1 () {40 vars in 655 bytes} [Mon Sep  6 06:34:47 2021] POST /auth => generated 49 bytes in 352 msecs (HTTP/1.1 422) 3 headers in 322 bytes (1 switches on core 0)
[pid: 10|app: 0|req: 1/2] 192.168.16.1 () {40 vars in 671 bytes} [Mon Sep  6 06:34:58 2021] POST /create_admin => generated 39 bytes in 145 msecs (HTTP/1.1 200) 3 headers in 304 bytes (1 switches on core 0)
[pid: 10|app: 0|req: 2/3] 192.168.16.1 () {40 vars in 655 bytes} [Mon Sep  6 06:35:02 2021] POST /auth => generated 77 bytes in 24 msecs (HTTP/1.1 200) 4 headers in 318 bytes (1 switches on core 1)
[pid: 14|app: 0|req: 2/4] 192.168.16.1 () {40 vars in 717 bytes} [Mon Sep  6 06:35:16 2021] GET /employee/7 => generated 30 bytes in 46 msecs (HTTP/1.1 200) 4 headers in 318 bytes (1 switches on core 1)
[pid: 14|app: 0|req: 3/5] 192.168.16.1 () {40 vars in 719 bytes} [Mon Sep  6 06:35:18 2021] GET /employee/lo => generated 47 bytes in 6 msecs (HTTP/1.1 422) 4 headers in 336 bytes (1 switches on core 0)
[pid: 11|app: 0|req: 1/6] 192.168.16.1 () {42 vars in 727 bytes} [Mon Sep  6 06:35:22 2021] POST /employee => generated 39 bytes in 279 msecs (HTTP/1.1 200) 4 headers in 318 bytes (1 switches on core 0)
[pid: 14|app: 0|req: 4/7] 192.168.16.1 () {42 vars in 727 bytes} [Mon Sep  6 06:35:24 2021] POST /employee => generated 44 bytes in 48 msecs (HTTP/1.1 422) 4 headers in 336 bytes (1 switches on core 1)
[pid: 14|app: 0|req: 5/8] 192.168.16.1 () {40 vars in 717 bytes} [Mon Sep  6 06:35:29 2021] GET /employee/7 => generated 30 bytes in 12 msecs (HTTP/1.1 200) 4 headers in 318 bytes (1 switches on core 0)
[pid: 11|app: 0|req: 2/9] 192.168.16.1 () {40 vars in 721 bytes} [Mon Sep  6 06:35:36 2021] GET /employee/all => generated 174 bytes in 15 msecs (HTTP/1.1 200) 4 headers in 319 bytes (1 switches on core 1)
[pid: 11|app: 0|req: 3/10] 192.168.16.1 () {40 vars in 721 bytes} [Mon Sep  6 06:35:43 2021] GET /employee/all => generated 174 bytes in 9 msecs (HTTP/1.1 200) 4 headers in 319 bytes (1 switches on core 0)
